Workbook

Sheet sum
A1: add_id | B1: s | C1: app_notes | D1: deadline_target | E1: add_posting | F1: add_how_apply | G1: good_match | H1: recruitment_officer | I1: app_status | J1: outcome | K1: network email | L1: when? | M1: institution | N1: location | O1: country | P1: add_rank | Q1: add_field | R1: add_category | S1: review_deadline | T1: other_link | U1: need_cover_letter | V1: need_RS | W1: need_TS
A2: fashion | D2: 45902 | E2: JOE | F2: https://fitnyc.interviewexchange.com/jobofferdetails.jsp?JOBID=190784 | G2: 1 | I2: late app | J2: no news | M2: Fashion Institute of Technology | N2: #VALUE! | O2: {=_FV(N2,"Name")} -> United States | P2: assistant | R2: research | S2: 45902 | U2: 1 | V2: 0 | W2: 1
A3: simon_frazer_1 | D3: 45931 | E3: EJM | F3: EJM | I3: completed | J3: no news | M3: Simon Fraser University | N3: #VALUE! | O3: {=_FV(N3,"Name")} -> United States | P3: assistant | Q3: applied micro | R3: research | S3: 45931 | T3: {=_FV(N3,"Name")} -> United States | U3: 1 | V3: 1 | W3: 1
A4: macmaster_1 | D4: 45931 | E4: EJM | F4: EJM | I4: completed | J4: rejected | M4: McMaster University | N4: #VALUE! | O4: {=_FV(N4,"Name")} -> United States | P4: assistant | Q4: applied micro | R4: research | S4: 45931 | U4: 1 | V4: 1 | W4: 1
A5: american_u_2 | D5: 45931 | E5: https://american.wd1.myworkdayjobs.com/AU/job/Main-Campus-Washington-DC/Assistant-Professor--Tenure-Track----Department-of-Politics--Governance---Economics_R2983-1 | I5: abandoned | J5: no news | M5: American University | N5: #VALUE! | O5: {=_FV(N5,"Name")} -> United States | P5: assistant | R5: research | S5: 45931 | U5: 1 | V5: 0 | W5: 1
A6: american_u_1 | D6: 45931 | E6: https://american.wd1.myworkdayjobs.com/en-US/AU/job/Assistant-Professor--Tenure-Track----Department-of-Environment--Development---Health_R2984 | I6: completed | J6: no news | M6: American University | N6: #VALUE! | O6: {=_FV(N6,"Name")} -> United States | P6: assistant | Q6: development | R6: research | S6: 45931 | U6: 1 | V6: 0 | W6: 1
A7: rovira_1 | D7: 45940 | E7: EJM | G7: 1 | H7: Ferran Mañé (e-mail: ferran.mane@urv.cat) | I7: completed | J7: no news | K7: YES | L7: 45976 | M7: Universitat Rovira i Virgili | N7: #VALUE! | O7: {=_FV(N7,"Name")} -> Spain | P7: assistant | R7: research | S7: 45940 | U7: 1 | V7: 0 | W7: 0
A8: waseda_1 | D8: 45940 | E8: JOE | F8: https://www.wasedapse.jp/en/fpse2/eng_input.php | G8: 1 | I8: abandoned | J8: no news | M8: Waseda University | N8: #VALUE! | O8: {=_FV(N8,"Name")} -> Japan | P8: assistant | Q8: applied micro | R8: research | S8: 45940 | T8: https://www.waseda.jp/fpse/pse/news-en/2025/08/05/24591/ | U8: 1 | V8: 1 | W8: 1
A9: babson_2 | D9: 45940 | E9: https://babson.peopleadmin.com/postings/6545 | I9: completed | J9: no news | M9: Babson College | N9: #VALUE! | O9: {=_FV(N9,"Name")} -> United States | P9: assistant | Q9: macroeconomics | R9: research | S9: 45940 | U9: 1 | V9: 1 | W9: 1
A10: babson_1 | D10: 45940 | E10: https://babson.peopleadmin.com/postings/6541 | I10: abandoned | J10: no news | M10: Babson College | N10: #VALUE! | O10: {=_FV(N10,"Name")} -> United States | P10: adjunct | R10: research | S10: 45940 | U10: 1 | V10: 0 | W10: 1
A11: tennessee | D11: 45945 | E11: https://apply.interfolio.com/172616 | I11: completed | J11: no news | M11: The University of Tennessee at Chattanooga | N11: #VALUE! | O11: {=_FV(N11,"Name")} -> United States | P11: assistant | R11: research | S11: 45945 | U11: 1 | V11: 1 | W11: 1
A12: oecd_1 | D12: 45945 | E12: EJM | F12: mathieu.miranda@oecd.org | I12: completed | J12: rejected | M12: OECD | N12: #VALUE! | O12: {=_FV(N12,"Name")} -> France | R12: research | S12: 45945 | T12: https://forms.office.com/Pages/ResponsePage.aspx?id=1MdBrGEfDUaw9PySWitHHPCJevCMDFdChZ_htgD0RItUN0NJUjcwQlFOQUhUU0dLSkdONVY3U1g3OS4u | U12: 1 | V12: 0 | W12: 0
A13: idb_1 | D13: 45945 | E13: https://jobs.iadb.org/job/Economics-Specialist/1922-en_US/ | I13: completed | J13: rejected | M13: IDB | N13: #VALUE! | O13: {=_FV(N13,"Name")} -> United States | R13: research | S13: 45945 | U13: 1 | V13: 0 | W13: 0
A14: cum_madrid_2 | D14: 45945 | E14: EJM | I14: late app | J14: no news | M14: Universidad Complutense de Madrid | N14: #VALUE! | O14: {=_FV(N14,"Name")} -> Spain | P14: assistant | R14: research | S14: 45945 | U14: 1 | V14: 0 | W14: 0
A15: cum_madrid_1 | D15: 45945 | E15: EJM | I15: late app | J15: no news | M15: Universidad Complutense de Madrid | N15: #VALUE! | O15: {=_FV(N15,"Name")} -> Spain | P15: assistant | R15: research | S15: 45945 | U15: 1 | V15: 0 | W15: 0
A16: chrisnew | D16: 45945 | E16: https://jobs.cnu.edu/postings/19812 | I16: completed | J16: no news | M16: Christopher Newport University | N16: #VALUE! | O16: {=_FV(N16,"Name")} -> United States | P16: assistant | R16: research | S16: 45945 | U16: 1 | V16: 0 | W16: 1
A17: berry_2 | D17: 45945 | E17: JOE | F17: https://berry.interviewexchange.com/static/clients/563BCM1/index.jsp;jsessionid=D6807F41311DBB7FA4BF3B5A2CEB7DC5 | H17: Prof. E. Frank Stephenson at efstephenson@berry.edu | I17: completed | J17: no news | M17: Berry College | N17: #VALUE! | O17: {=_FV(N17,"Name")} -> United States | P17: assistant | Q17: Economics | R17: research | S17: 46142 | U17: 1 | V17: 0 | W17: 1
A18: u_chile_ig | D18: 45947 | E18: JOE | G18: 1 | I18: completed | J18: no news | K18: YES | L18: 45976 | M18: Universidad de Chile | N18: #VALUE! | O18: {=_FV(N18,"Name")} -> Chile | P18: assistant | R18: research | S18: 45992 | U18: 1 | V18: 0 | W18: 0
A19: utrecht | D19: 45950 | E19: EJM | F19: https://www.uu.nl/en/organisation/working-at-utrecht-university/jobs/lecturer-in-applied-economics | G19: 1 | H19: Marcel Boumans m.j.boumans@uu.nl | I19: completed | J19: rejected | K19: YES | L19: 45976 | M19: Utrecht University | N19: #VALUE! | O19: {=_FV(N19,"Name")} -> Netherlands | P19: lecturer | R19: research | S19: 45959 | U19: 1 | V19: 0 | W19: 0
A20: vassar | D20: 45950 | E20: EJM | G20: 1 | H20: Sarah Pearlman sapearlman@vassar.edu. | I20: completed | J20: no news | M20: Vassar College | N20: #VALUE! | O20: {=_FV(N20,"Name")} -> United States | P20: assistant | R20: research | S20: 45964 | U20: 1 | V20: 1 | W20: 1
A21: utokyo | D21: 45950 | E21: JOE | I21: completed | J21: no news | M21: UTokyo Economic Consulting Inc. | N21: #VALUE! | O21: {=_FV(N21,"Name")} -> Japan | P21: assistant | R21: research | S21: 46022 | U21: 1 | V21: 0 | W21: 0
A22: utah | D22: 45950 | E22: https://utah.peopleadmin.com/postings/188619 | I22: completed | J22: no news | M22: The University of Utah | N22: #VALUE! | O22: {=_FV(N22,"Name")} -> United States | P22: assistant | R22: research | S22: 45960 | U22: 1 | V22: 1 | W22: 1
A23: uc_davis | D23: 45950 | E23: EJM | F23: https://apptrkr.com/6572257 | I23: completed | J23: no news | M23: UC Davis | N23: #VALUE! | O23: {=_FV(N23,"Name")} -> United States | P23: assistant | Q23: agriculture | R23: research | S23: 45964 | U23: 1 | V23: 1 | W23: 1
A24: uab | D24: 45950 | E24: EJM | I24: completed | J24: no news | M24: Universitat Autònoma de Barcelona | N24: #VALUE! | O24: {=_FV(N24,"Name")} -> Spain | P24: assistant | R24: research | S24: 45963 | U24: 1 | V24: 1 | W24: 0
A25: misurri_col | D25: 45950 | E25: JOE | F25: https://erecruit.umsystem.edu/psc/tamext/COLUM/HRMS/c/HRS_HRAM_FL.HRS_CG_SEARCH_FL.GBL?Page=HRS_APP_SCHJOB_FL&Action=U | I25: completed | J25: no news | M25: University of Missouri-Columbia | N25: #VALUE! | O25: {=_FV(N25,"Name")} -> United States | P25: assistant | R25: research | S25: 45961 | U25: 1 | V25: 1 | W25: 1
A26: kobe | D26: 45950 | E26: JOE | F26: need the one of american history | G26: 1 | I26: completed | J26: no news | M26: Kobe University | N26: #VALUE! | O26: {=_FV(N26,"Name")} -> Japan | P26: assistant | R26: research | S26: 45961 | U26: 1 | V26: 0 | W26: 0
A27: idb_2 | D27: 45950 | E27: https://jobs.iadb.org/job/Development-Effectiveness-and-Impact-Evaluation-Consultant/1937-en_US/ | I27: completed | J27: no news | M27: IDB | N27: #VALUE! | O27: {=_FV(N27,"Name")} -> United States | R27: research | S27: 45954 | U27: 1 | V27: 0 | W27: 0
A28: haverford | D28: 45950 | E28: JOE | F28: https://apply.interfolio.com/171810 | I28: completed | J28: no news | M28: Haverford College | N28: #VALUE! | O28: {=_FV(N28,"Name")} -> United States | P28: assistant | R28: research | S28: 45957 | U28: 1 | V28: 1 | W28: 1
A29: getty | D29: 45950 | E29: JOE | F29: https://gettysburg.peopleadmin.com/postings/6014 | I29: completed | J29: rejected | M29: Gettysburg College | N29: #VALUE! | O29: {=_FV(N29,"Name")} -> United States | P29: assistant | R29: research | S29: 45962 | U29: 1 | V29: 1 | W29: 1
A30: darthmouth | D30: 45950 | E30: EJM | I30: completed | J30: rejected | M30: Dartmouth College | N30: #VALUE! | O30: {=_FV(N30,"Name")} -> United States | P30: lecturer | R30: research | S30: 45992 | U30: 1 | V30: 0 | W30: 0
A31: boston | D31: 45950 | E31: EJM | I31: completed | J31: no news | M31: Boston College | N31: #VALUE! | O31: {=_FV(N31,"Name")} -> United States | P31: assistant | R31: research | S31: 46022 | U31: 1 | V31: 0 | W31: 0
A32: berry_1 | D32: 45950 | E32: JOE | F32: https://berry.interviewexchange.com/static/clients/563BCM1/index.jsp | H32: Dr. Jamie Sharpe, at jsharpe@berry.edu | I32: completed | J32: no news | M32: Berry College | N32: #VALUE! | O32: {=_FV(N32,"Name")} -> United States | P32: assistant | Q32: Data Analytics | R32: research | S32: 46142 | U32: 1 | V32: 0 | W32: 1
A33: baylor | D33: 45950 | E33: JOE | F33: https://apply.interfolio.com/172650 | I33: completed | J33: no news | M33: Baylor University | N33: #VALUE! | O33: {=_FV(N33,"Name")} -> United States | P33: assistant | R33: research | S33: 46157 | U33: 1 | V33: 1 | W33: 1
A34: andersen | D34: 45950 | E34: JOE | I34: completed | J34: no news | M34: Andersen Institute for Finance and Economics | N34: #VALUE! | O34: {=_FV(N34,"Name")} -> United States | R34: research | S34: 45950 | U34: 1 | V34: 0 | W34: 0
A35: tamu_1 | D35: 45955 | E35: https://apply.interfolio.com/173294 | G35: 1 | I35: completed | J35: no news | K35: YES | L35: 45965 | M35: Texas A&M | N35: #VALUE! | O35: {=_FV(N35,"Name")} -> United States | P35: assistant | Q35: applied micro | R35: research | S35: 45962 | U35: 1 | V35: 1 | W35: 1
A36: queensland | D36: 45955 | E36: JOE | G36: 1 | H36: Professor Claudio Mezzetti (c.mezzetti@uq.edu.au) | I36: completed | J36: no news | K36: YES | L36: 45965 | M36: University of Quesnland | N36: #VALUE! | O36: {=_FV(N36,"Name")} -> Australia | P36: assistant | R36: research | S36: 45969 | U36: 1 | V36: 0 | W36: 0
A37: pompeu_fabra | D37: 45955 | E37: EJM | G37: 1 | I37: completed | J37: no news | K37: YES | L37: 45965 | M37: Universitat Pompeu Fabra | N37: #VALUE! | O37: {=_FV(N37,"Name")} -> Barcelona | P37: assistant | R37: research | S37: 45963 | U37: 1 | V37: 1 | W37: 1
A38: monash | D38: 45955 | E38: EJM | G38: 1 | H38: Arthur Campbell (arthur.campbell@monash.edu) | I38: completed | J38: no news | K38: YES | L38: 45965 | M38: Monash University | N38: #VALUE! | O38: {=_FV(N38,"Name")} -> Australia | P38: assistant | R38: research | S38: 45962 | U38: 1 | V38: 0 | W38: 0
A39: u_chicago | D39: 45955 | E39: https://apply.interfolio.com/172477 | I39: completed | J39: no news | M39: University of Chicago | N39: #VALUE! | O39: {=_FV(N39,"Name")} -> United States | P39: assistant | R39: research | S39: 46203 | U39: 1 | V39: 1 | W39: 1
A40: tulane | D40: 45955 | E40: https://apply.interfolio.com/172687 | I40: completed | J40: no news | M40: Tulane University | N40: #VALUE! | O40: {=_FV(N40,"Name")} -> United States | P40: teaching | R40: research | S40: 46010 | U40: 1 | V40: 0 | W40: 1
...

Sheet timeline
A1: date | B1: app_id | C1: comment
A2: 45930 | C2: gathering info from AEA JOE, stopped @ Bates College
A3: 45931 | C3: gathering the applications that I'm most interested in
A4: 45944 | B4: simon_frazer_1 | C4: app sent
A5: 45944 | B5: macmaster_1 | C5: app sent
A6: 45944 | C6: applied for the Europe UniCredit Best Paper Award
A7: 45945 | C7: gathered info for postings
A8: 45945 | B8: rovira_1 | C8: app sent
A9: 45946 | C9: gathered info for 11 postings and struggle with interfolio
A10: 45946 | B10: american_u_1 | C10: app sent
A11: 45946 | B11: analysis_1 | C11: app sent
A12: 45946 | B12: analysis_2 | C12: app sent
A13: 45946 | B13: u_chile_ig | C13: app sent
A14: 45946 | B14: oecd_1 | C14: app sent
A15: 45947 | B15: idb_1 | C15: app sent
A16: 45947 | B16: will_college_1 | C16: app sent
A17: 45947 | B17: bates_1 | C17: app sent
A18: 45947 | B18: haverford | C18: app sent
A19: 45947 | B19: a_paris | C19: app sent
A20: 45947 | C20: gathered info for 11 postings and struggle with interfolio
A21: 45947 | B21: utrecht | C21: app sent
A22: 45947 | B22: ecole | C22: app sent
A23: 45947 | B23: mit | C23: app sent
A24: 45947 | B24: uc_davis | C24: app sent
A25: 45947 | B25: manheim | C25: app sent
A26: 45948 | C26: gathered 10 postings from JOE stoped at Bowdoin
A27: 45948 | B27: berry_2 | C27: app sent
A28: 45948 | B28: berry_1 | C28: app sent
A29: 45948 | B29: idb_2 | C29: app sent
A30: 45948 | B30: kobe | C30: app sent
A31: 45948 | B31: utokyo | C31: app sent
A32: 45948 | B32: baylor | C32: app sent
A33: 45948 | B33: stanford | C33: app sent
A34: 45948 | B34: bologna | C34: app sent
A35: 45948 | B35: u_virginia | C35: waiting for recs
A36: 45948 | B36: tamu_1 | C36: went over cover letter
A37: 45949 | B37: columbia | C37: app sent
A38: 45949 | B38: u_virginia | C38: app sent
A39: 45949 | C39: added more than 10 posting from EJM stopped @ prague posting
A40: 45949 | B40: stockholm_1 | C40: app sent
...

Sheet stats
A1: Total apps | B1: =COUNTA(sum!A:A) -1 -> 308 | C1: =COUNTIF(sum!I:I, "completed")/(B1-COUNTIF(sum!I:I, "abandoned")-COUNTIF(sum!I:I, "late app")) -> 1 | D1: =COUNTIF(sum!I:I, "completed") -> 297
A2: good match | B2: =COUNTA(sum!G:G) -1 -> 53 | C2: =COUNTIFS(sum!I:I,"completed", sum!G:G, "<>") / B2 -> 0.96226415
A3: emails | B3: =COUNTA(sum!K:K) -1 -> 59 | C3: =COUNTIFS(sum!I:I,"completed", sum!K:K, "<>") / B3 -> 1
A5: Outcomes | B5: =COUNTA(sum!J:J) -1 -> 308 | C5: =B5/B1 -> 1
A6: no news | B6: =COUNTIFS(sum!J:J,"no news") -> 272 | C6: =B6/$B$5 -> 0.88311688
A7: rejected | B7: =COUNTIFS(sum!J:J,"rejected") -> 28 | C7: =B7/$B$5 -> 0.090909091
A8: interview | B8: =COUNTIFS(sum!J:J,"interview") + COUNTIFS(sum!J:J,"fly out") + COUNTIFS(sum!J:J,"offer") -> 8 | C8: =B8/$B$5 -> 0.025974026
A9: fly out | B9: =COUNTIFS(sum!J:J,"fly out") + COUNTIFS(sum!J:J,"offer") -> 1 | C9: =B9/$B$5 -> 0.0032467532
A10: offer | B10: =COUNTIFS(sum!J:J,"offer") -> 0 | C10: =B10/$B$5 -> 0
A11: *may be not updated because I forgot to update the "sum" page. See timeline for accurate status of applications
